2021-03-18 15:44:27,134 INFO Starting batch -- number of file: 90
2021-03-18 15:44:27,134 INFO Source: dummy
2021-03-18 15:44:27,134 INFO Python netcdf: netCDF4
2021-03-18 15:44:27,134 INFO Starting: v0_day_a_a_1900-1909.nc
2021-03-18 15:44:27,135 INFO Log file: logs_02/v0_day_a_a_1900-1909__qclog_20210318.txt
2021-03-18 15:44:27,135 INFO Done -- error count 2
2021-03-18 15:44:27,135 INFO Starting: v0_day_a_b_1900-1909.nc
2021-03-18 15:44:27,135 INFO Log file: logs_02/v0_day_a_b_1900-1909__qclog_20210318.txt
2021-03-18 15:44:27,136 ERROR Exception has occured
Traceback (most recent call last):
  File "/data/Repositories/git/shared/ceda-cc/ceda_cc/p3/utils_c4.py", line 261, in runChecks
    c()  # run check
  File "/data/Repositories/git/shared/ceda-cc/ceda_cc/p3/utils_c4.py", line 680, in do_check_ga
    ok &= self.test( len(mm)  == 0, 'Variable [%s] has incorrect attributes: %s' % (varName, strmm3(mm)), part=True )
  File "/data/Repositories/git/shared/ceda-cc/ceda_cc/p3/utils_c4.py", line 241, in test
    self.log_error(msg)
  File "/data/Repositories/git/shared/ceda-cc/ceda_cc/p3/utils_c4.py", line 203, in log_error
    self.logMessage( '%s.%s: FAILED:: %s' % (self.id,self.getCheckId(),msg), error=True )
  File "/data/Repositories/git/shared/ceda-cc/ceda_cc/p3/utils_c4.py", line 168, in logMessage
    assert self.abortMessageCount < 0 or self.abortMessageCount > self.messageCount, 'Raising error [TESTX01], perhaps for testing'
AssertionError: Raising error [TESTX01], perhaps for testing

During handling of the above exception, another exception occurred:

Traceback (most recent call last):
  File "/data/Repositories/git/shared/ceda-cc/ceda_cc/p3/c4_run.py", line 332, in __init__
    self.cc.checkFile( f, log=fLogger,attributeMappings=c4i.attributeMappings, getdrs=c4i.getdrs )
  File "/data/Repositories/git/shared/ceda-cc/ceda_cc/p3/c4_run.py", line 229, in checkFile
    self.cga.check( self.ga, self.va, self.cfn.var, vGroup, self.vocabs, self.cfn.fnParts )
  File "/data/Repositories/git/shared/ceda-cc/ceda_cc/p3/utils_c4.py", line 495, in check
    self.runChecks()
  File "/data/Repositories/git/shared/ceda-cc/ceda_cc/p3/utils_c4.py", line 270, in runChecks
    raise loggedException
xceptions.loggedException
