Starting file v0_day_a_b_1900-1909.nc
C4.001.001: [parse_filename]: OK
C4.001.002: [parse_filename_timerange]: OK
C4.001.004: [file_name_extra]: OK
C4.002.001: [global_ncattribute_present]: OK
C4.002.003: [variable_type]: OK
C4.002.004: [variable_ncattribute_present]: OK
Exception has occured
Traceback (most recent call last):
  File "/data/Repositories/git/shared/ceda-cc/ceda_cc/p3/utils_c4.py", line 261, in runChecks
    c()  # run check
  File "/data/Repositories/git/shared/ceda-cc/ceda_cc/p3/utils_c4.py", line 680, in do_check_ga
    ok &= self.test( len(mm)  == 0, 'Variable [%s] has incorrect attributes: %s' % (varName, strmm3(mm)), part=True )
  File "/data/Repositories/git/shared/ceda-cc/ceda_cc/p3/utils_c4.py", line 241, in test
    self.log_error(msg)
  File "/data/Repositories/git/shared/ceda-cc/ceda_cc/p3/utils_c4.py", line 203, in log_error
    self.logMessage( '%s.%s: FAILED:: %s' % (self.id,self.getCheckId(),msg), error=True )
  File "/data/Repositories/git/shared/ceda-cc/ceda_cc/p3/utils_c4.py", line 168, in logMessage
    assert self.abortMessageCount < 0 or self.abortMessageCount > self.messageCount, 'Raising error [TESTX01], perhaps for testing'
AssertionError: Raising error [TESTX01], perhaps for testing
C4.100.001: [exception]: FAILED:: Exception has occured
Traceback (most recent call last):
  File "/data/Repositories/git/shared/ceda-cc/ceda_cc/p3/utils_c4.py", line 261, in runChecks
    c()  # run check
  File "/data/Repositories/git/shared/ceda-cc/ceda_cc/p3/utils_c4.py", line 680, in do_check_ga
    ok &= self.test( len(mm)  == 0, 'Variable [%s] has incorrect attributes: %s' % (varName, strmm3(mm)), part=True )
  File "/data/Repositories/git/shared/ceda-cc/ceda_cc/p3/utils_c4.py", line 241, in test
    self.log_error(msg)
  File "/data/Repositories/git/shared/ceda-cc/ceda_cc/p3/utils_c4.py", line 203, in log_error
    self.logMessage( '%s.%s: FAILED:: %s' % (self.id,self.getCheckId(),msg), error=True )
  File "/data/Repositories/git/shared/ceda-cc/ceda_cc/p3/utils_c4.py", line 168, in logMessage
    assert self.abortMessageCount < 0 or self.abortMessageCount > self.messageCount, 'Raising error [TESTX01], perhaps for testing'
AssertionError: Raising error [TESTX01], perhaps for testing

During handling of the above exception, another exception occurred:

Traceback (most recent call last):
  File "/data/Repositories/git/shared/ceda-cc/ceda_cc/p3/c4_run.py", line 332, in __init__
    self.cc.checkFile( f, log=fLogger,attributeMappings=c4i.attributeMappings, getdrs=c4i.getdrs )
  File "/data/Repositories/git/shared/ceda-cc/ceda_cc/p3/c4_run.py", line 229, in checkFile
    self.cga.check( self.ga, self.va, self.cfn.var, vGroup, self.vocabs, self.cfn.fnParts )
  File "/data/Repositories/git/shared/ceda-cc/ceda_cc/p3/utils_c4.py", line 495, in check
    self.runChecks()
  File "/data/Repositories/git/shared/ceda-cc/ceda_cc/p3/utils_c4.py", line 270, in runChecks
    raise loggedException
xceptions.loggedException
